Workbook
Name BPC_TIME: [1]Selection!$I$11
Name DESC_CYTIME: [1]Selection!$E$21
Name DESC_ENTITY: [1]Selection!$D$13
Name DESC_FUND: [1]Selection!$D$15
Name VIEW_C_DATASRC: [1]Selection!$C$12
Name VIEW_CURRENCY: [1]Selection!$C$9

Sheet V1
A1: 整理 分类 | B1: S4 OCOA | C1: GCOA | D1: OCOA name (CN) | E1: SUN Code | F1: Stat | G1: IFRS | H1: OLD CAS | I1: FAM | J1: ILP | K1: OCOA name (EN) | L1: ETL Scope | M1: 重复次数 | N1: 仅I档有数的科目 | O1: 备注 | P1: need to follow up
A2: Investment | B2: 1000002000 | C2: 100000 | D2: 持有至到期投资-成本 | E2: 120601 | F2: Y | G2: Y | H2: NA | I2: Y | J2: NA | K2: Held to Maturity Securities-Nominal Value,FAM excl | L2: =IF(ISERROR(VLOOKUP(B2,'ETL Scope'!I:I,1,0)),"NA","ETL") -> NA | M2: =COUNTIF('Data-WK'!A:A,'V1'!B:B) -> 1 | N2: =VLOOKUP(E2,'IFRS only'!A:A,1,0) -> #N/A
A3: Investment | B3: 1000002010 | C3: 100000 | D3: 持有至到期投资-溢折价摊销 | E3: 120602 | F3: Y | G3: Y | H3: NA | I3: Y | J3: NA | K3: Held to Maturity Secur-Unamort Prem/Disc,FAM excl | L3: =IF(ISERROR(VLOOKUP(B3,'ETL Scope'!I:I,1,0)),"NA","ETL") -> NA | M3: =COUNTIF('Data-WK'!A:A,'V1'!B:B) -> 1 | N3: =VLOOKUP(E3,'IFRS only'!A:A,1,0) -> #N/A
A4: Investment | B4: 1000002020 | C4: 100000 | D4: 持有至到期投资-减值准备 | E4: 120604 | F4: Y | G4: Y | H4: NA | I4: NA | J4: NA | K4: Held to Maturity Secur-Prov for Impairment,FAMexcl | L4: =IF(ISERROR(VLOOKUP(B4,'ETL Scope'!I:I,1,0)),"NA","ETL") -> NA | M4: =COUNTIF('Data-WK'!A:A,'V1'!B:B) -> 1 | N4: =VLOOKUP(E4,'IFRS only'!A:A,1,0) -> #N/A
A5: Investment | B5: 1010000000 | C5: 101000 | D5: 可供出售金融资产-债券(IFRS) | E5: 120506 | F5: NA | G5: Y | H5: NA | I5: Y | J5: NA | K5: Bonds, Available for Sale, FAM excl | L5: =IF(ISERROR(VLOOKUP(B5,'ETL Scope'!I:I,1,0)),"NA","ETL") -> NA | M5: =COUNTIF('Data-WK'!A:A,'V1'!B:B) -> 1 | N5: =VLOOKUP(E5,'IFRS only'!A:A,1,0) -> 120506
A6: Investment | B6: 1010002000 | C6: 101000 | D6: 可供出售金融资产-债券-成本 | E6: 120501 | F6: Y | G6: Y | H6: NA | I6: Y | J6: NA | K6: Available for Sales Securities-NominalVal,FAM excl | L6: =IF(ISERROR(VLOOKUP(B6,'ETL Scope'!I:I,1,0)),"NA","ETL") -> NA | M6: =COUNTIF('Data-WK'!A:A,'V1'!B:B) -> 7 | N6: =VLOOKUP(E6,'IFRS only'!A:A,1,0) -> #N/A
A7: Investment | B7: 1010002010 | C7: 101000 | D7: 可供出售金融资产-债券-溢折价摊销 | E7: 120502 | F7: Y | G7: Y | H7: NA | I7: Y | J7: NA | K7: AFS Securities-Unamort Prem/Disc, FAM excl | L7: =IF(ISERROR(VLOOKUP(B7,'ETL Scope'!I:I,1,0)),"NA","ETL") -> NA | M7: =COUNTIF('Data-WK'!A:A,'V1'!B:B) -> 6 | N7: =VLOOKUP(E7,'IFRS only'!A:A,1,0) -> #N/A
A8: Investment | B8: 1010002020 | C8: 101000 | D8: 可供出售金融资产-债券-公允价值变动 | E8: 120504 | F8: Y | G8: Y | H8: NA | I8: Y | J8: NA | K8: AFS Securities-Mark to Market change,FAM excl | L8: =IF(ISERROR(VLOOKUP(B8,'ETL Scope'!I:I,1,0)),"NA","ETL") -> NA | M8: =COUNTIF('Data-WK'!A:A,'V1'!B:B) -> 7 | N8: =VLOOKUP(E8,'IFRS only'!A:A,1,0) -> #N/A
A9: Investment | B9: 1010002021 | C9: 101000 | D9: 可供出售金融资产-债券-公允价值变动(手工) | E9: 120504 | F9: Y | G9: NA | H9: NA | I9: NA | J9: NA | K9: AFS Securities-Mark to Market change,FAM excl | L9: =IF(ISERROR(VLOOKUP(B9,'ETL Scope'!I:I,1,0)),"NA","ETL") -> NA | M9: =COUNTIF('Data-WK'!A:A,'V1'!B:B) -> 0 | N9: =VLOOKUP(E9,'IFRS only'!A:A,1,0) -> #N/A
A10: Investment | B10: 1010002030 | C10: 101000 | D10: 可供出售金融资产-减值准备-债券 | E10: 120505 | F10: Y | G10: Y | H10: NA | I10: Y | J10: NA | K10: AFS Securities-Prov for Impairment,FAM excl | L10: =IF(ISERROR(VLOOKUP(B10,'ETL Scope'!I:I,1,0)),"NA","ETL") -> NA | M10: =COUNTIF('Data-WK'!A:A,'V1'!B:B) -> 7 | N10: =VLOOKUP(E10,'IFRS only'!A:A,1,0) -> #N/A
A11: Investment | B11: 1030000000 | C11: 103000 | D11: 公允价值选择权-债券(IFRS) | E11: 121001 | F11: NA | G11: Y | H11: NA | I11: Y | J11: NA | K11: Bonds, Fair Value Option, FAM excl | L11: =IF(ISERROR(VLOOKUP(B11,'ETL Scope'!I:I,1,0)),"NA","ETL") -> NA | M11: =COUNTIF('Data-WK'!A:A,'V1'!B:B) -> 12 | N11: =VLOOKUP(E11,'IFRS only'!A:A,1,0) -> 121001
A12: Investment | B12: 1030000010 | C12: 103000 | D12: 交易性金融资产-债券-成本-ILP | E12: 新增 | F12: Y | G12: Y | H12: NA | I12: NA | J12: Y | K12: 待Group 决定 | L12: =IF(ISERROR(VLOOKUP(B12,'ETL Scope'!I:I,1,0)),"NA","ETL") -> NA | M12: =COUNTIF('Data-WK'!A:A,'V1'!B:B) -> 0 | N12: =VLOOKUP(E12,'IFRS only'!A:A,1,0) -> #N/A
A13: Investment | B13: 1030000020 | C13: 103000 | D13: 交易性金融资产-债券-公允价值变动-ILP | E13: 12010102 | F13: Y | G13: Y | H13: NA | I13: NA | J13: Y-D | K13: 待Group 决定 | L13: =IF(ISERROR(VLOOKUP(B13,'ETL Scope'!I:I,1,0)),"NA","ETL") -> NA | M13: =COUNTIF('Data-WK'!A:A,'V1'!B:B) -> 0 | N13: =VLOOKUP(E13,'IFRS only'!A:A,1,0) -> #N/A
A14: Term Deposit | B14: 1140000000 | C14: 114000 | D14: 定期存款-1年及以上 | E14: 1204020101;1204020102;1204020103;1204020104;1204020105;1204020106;1204020107;1204020108;1204020109;1204020110;1204020111;1204020112;1204020113;1204020114;1204020115;1204020116;1204020141;1204020142;1204020143;1204020144;1204020145;1204020146;1204020147;1204020148;1204020149;1204020201;1204020202;1204020203;1204020204;1204020205;1204020206;1204020207;1204020208;1204020209;1204020210;1204020211;1204020212;1204020213;1204020214;1204020215;1204020216;1204020241;1204020242;1204020243;1204020244;1204020245;1204020246;1204020247;1204020248;1204020249;1204020301;1204020302;1204020303;1204020304;1204020305;1204020306;1204020307;1204020308;1204020309;1204020310;1204020311;1204020312;1204020313;1204020314;1204020315;1204020316;1204020341;1204020342;1204020343;1204020344;1204020345;1204020346;1204020347;1204020348;1204020349 | F14: Y | G14: Y | H14: NA | I14: Y | J14: NA | K14: Long Term Deposits>=1 year, FAM excl | L14: =IF(ISERROR(VLOOKUP(B14,'ETL Scope'!I:I,1,0)),"NA","ETL") -> NA | M14: =COUNTIF('Data-WK'!A:A,'V1'!B:B) -> 75 | N14: =VLOOKUP(E14,'IFRS only'!A:A,1,0) -> #VALUE!
A15: Term Deposit | B15: 1140002000 | C15: 114000 | D15: 存出资本保证金-1年及以上 | E15: 160102 | F15: Y | G15: Y | H15: NA | I15: NA | J15: NA | K15: Statutory Deposit, FAM excl | P15: 待Group决定
A16: Term Deposit | B16: 1140003000 | C16: 114000 | D16: 协议存款 | E16: 1204030101;1204030102;1204030103;1204030104;1204030105;1204030106;1204030107;1204030108;1204030109;1204030110;1204030111;1204030112;1204030113;1204030114;1204030115;1204030116;1204030141;1204030142;1204030143;1204030144;1204030145;1204030146;1204030147;1204030148;1204030149;1204030150;1204030151 | F16: Y | G16: Y | H16: NA | I16: NA | J16: NA | K16: 待Group 决定 | L16: =IF(ISERROR(VLOOKUP(B16,'ETL Scope'!I:I,1,0)),"NA","ETL") -> NA | M16: =COUNTIF('Data-WK'!A:A,'V1'!B:B) -> 0 | N16: =VLOOKUP(E16,'IFRS only'!A:A,1,0) -> #VALUE! | P16: 待Group决定
A17: Term Deposit | B17: 1140110000 | C17: 114011 | D17: 定期存款-1年期以下 | E17: 1204010101;1204010102;1204010103;1204010104;1204010105;1204010106;1204010107;1204010108;1204010109;1204010110;1204010111;1204010112;1204010113;1204010114;1204010115;1204010116;1204010141;1204010142;1204010143;1204010144;1204010145;1204010146;1204010147;1204010148;1204010149;1204010201;1204010202;1204010203;1204010204;1204010205;1204010206;1204010207;1204010208;1204010209;1204010210;1204010211;1204010212;1204010213;1204010214;1204010215;1204010216;1204010241;1204010242;1204010243;1204010244;1204010245;1204010247;1204010248;1204010249;1204010250;1204010251;1204010301;1204010302;1204010303;1204010304;1204010305;1204010306;1204010307;1204010308;1204010309;1204010310;1204010311;1204010312;1204010313;1204010314;1204010315;1204010341;1204010342;1204010343;1204010344;1204010345;1204010346;1204010347;1204010348;1204010349 | F17: Y | G17: Y | H17: NA | I17: Y | J17: NA | K17: Non Neg TDs > 90 days <1 year, FAM excl | L17: =IF(ISERROR(VLOOKUP(B17,'ETL Scope'!I:I,1,0)),"NA","ETL") -> NA | M17: =COUNTIF('Data-WK'!A:A,'V1'!B:B) -> 75 | N17: =VLOOKUP(E17,'IFRS only'!A:A,1,0) -> #VALUE!
A18: Investment | B18: 1143010000 | C18: 114301 | D18: 债券逆回购-1年及以上-面值 | E18: 12030101 | F18: Y | G18: Y | H18: NA | I18: Y | J18: NA | K18: Reverse Repo >=1 year, FAM excl | L18: =IF(ISERROR(VLOOKUP(B18,'ETL Scope'!I:I,1,0)),"NA","ETL") -> NA | M18: =COUNTIF('Data-WK'!A:A,'V1'!B:B) -> 1 | N18: =VLOOKUP(E18,'IFRS only'!A:A,1,0) -> #N/A
A19: Investment | B19: 1143011000 | C19: 114301 | D19: 债券逆回购-1年及以上-面值(手工) | E19: 12030101 | F19: Y | G19: Y | H19: NA | I19: NA | J19: Y | K19: Reverse Repo >=1 year | L19: =IF(ISERROR(VLOOKUP(B19,'ETL Scope'!I:I,1,0)),"NA","ETL") -> NA | M19: =COUNTIF('Data-WK'!A:A,'V1'!B:B) -> 1 | N19: =VLOOKUP(E19,'IFRS only'!A:A,1,0) -> #N/A
A20: Investment | B20: 1143110000 | C20: 114311 | D20: 债券逆回购-3个月至1年-面值 | E20: 12030101 | F20: Y | G20: Y | H20: NA | I20: Y | J20: NA | K20: Reverse Repo >90 days <1 year, FAM excl | L20: =IF(ISERROR(VLOOKUP(B20,'ETL Scope'!I:I,1,0)),"NA","ETL") -> NA | M20: =COUNTIF('Data-WK'!A:A,'V1'!B:B) -> 1 | N20: =VLOOKUP(E20,'IFRS only'!A:A,1,0) -> #N/A
A21: Investment | B21: 1143111000 | C21: 114311 | D21: 债券逆回购-3个月至1年-面值(手工) | E21: 12030101 | F21: Y | G21: Y | H21: NA | I21: Y | J21: Y | K21: Reverse Repo >90 days <1 year
A22: Investment | B22: 1240000000 | C22: 124000 | D22: 贷款及应收款项-非标投资(有抵押)-本金 | E22: 120801 | F22: Y | G22: Y | H22: NA | I22: Y | J22: NA | K22: Collateral & Guaranteed Loans, FAM excl | L22: =IF(ISERROR(VLOOKUP(B22,'ETL Scope'!I:I,1,0)),"NA","ETL") -> NA | M22: =COUNTIF('Data-WK'!A:A,'V1'!B:B) -> 1 | N22: =VLOOKUP(E22,'IFRS only'!A:A,1,0) -> #N/A
A23: Insurance cash items | B23: 1243000000 | C23: 124300 | D23: 保户质押贷款-本金 | E23: 120701 | F23: Y | G23: Y | H23: NA | I23: NA | J23: NA | K23: Policy Loans | L23: =IF(ISERROR(VLOOKUP(B23,'ETL Scope'!I:I,1,0)),"NA","ETL") -> NA | M23: =COUNTIF('Data-WK'!A:A,'V1'!B:B) -> 1 | N23: =VLOOKUP(E23,'IFRS only'!A:A,1,0) -> #N/A
A24: Investment | B24: 1245002000 | C24: 124500 | D24: 贷款及应收款项-非标投资(无抵押)-本金 | E24: 120801;120804; | F24: Y | G24: Y | H24: NA | I24: Y | J24: NA | K24: Unsecured & Non-guaranteed Loans, FAM excl | L24: =IF(ISERROR(VLOOKUP(B24,'ETL Scope'!I:I,1,0)),"NA","ETL") -> NA | M24: =COUNTIF('Data-WK'!A:A,'V1'!B:B) -> 2 | N24: =VLOOKUP(E24,'IFRS only'!A:A,1,0) -> #N/A
A25: Investment | B25: 1300000000 | C25: 130000 | D25: 交易性金融资产-股票供股权-成本-ILP | E25: 12010301;12010302;12020103 | F25: Y | G25: Y | H25: NA | I25: Y | J25: Y | K25: Derivatives Assets,Fair Value Option,FAM excl | L25: =IF(ISERROR(VLOOKUP(B25,'ETL Scope'!I:I,1,0)),"NA","ETL") -> NA | M25: =COUNTIF('Data-WK'!A:A,'V1'!B:B) -> 3 | N25: =VLOOKUP(E25,'IFRS only'!A:A,1,0) -> #N/A
A26: Investment | B26: 1410000110 | C26: 141000 | D26: 可供出售金融资产-股票-成本 | E26: 120501;120504 | F26: Y | G26: Y | H26: NA | I26: Y | J26: NA | K26: 待Group 决定 | L26: =IF(ISERROR(VLOOKUP(B26,'ETL Scope'!I:I,1,0)),"NA","ETL") -> NA | M26: =COUNTIF('Data-WK'!A:A,'V1'!B:B) -> 0 | N26: =VLOOKUP(E26,'IFRS only'!A:A,1,0) -> #N/A
A27: Investment | B27: 1410000120 | C27: 141000 | D27: 可供出售金融资产-股票-公允价值变动 | E27: 120504 | F27: Y | G27: Y | H27: NA | I27: Y | J27: NA | K27: 待Group 决定 | L27: =IF(ISERROR(VLOOKUP(B27,'ETL Scope'!I:I,1,0)),"NA","ETL") -> NA | M27: =COUNTIF('Data-WK'!A:A,'V1'!B:B) -> 0 | N27: =VLOOKUP(E27,'IFRS only'!A:A,1,0) -> #N/A
A28: Investment | B28: 1410000121 | C28: 141000 | D28: 可供出售金融资产-股票-公允价值变动(手工) | E28: 120504 | F28: Y | G28: NA | H28: NA | I28: NA | J28: NA | K28: 待Group 决定 | L28: =IF(ISERROR(VLOOKUP(B28,'ETL Scope'!I:I,1,0)),"NA","ETL") -> NA | M28: =COUNTIF('Data-WK'!A:A,'V1'!B:B) -> 0 | N28: =VLOOKUP(E28,'IFRS only'!A:A,1,0) -> #N/A
A29: Investment | B29: 1410000130 | C29: 141000 | D29: 可供出售金融资产-减值准备-股票 | E29: 120505 | F29: Y | G29: Y | H29: NA | I29: Y | J29: NA | K29: 待Group 决定
A30: Investment | B30: 1413000110 | C30: 141300 | D30: 可供出售金融资产-基金-成本 | E30: 120501;120504;120505 | F30: Y | G30: Y | H30: NA | I30: Y | J30: NA | K30: 待Group 决定 | L30: =IF(ISERROR(VLOOKUP(B30,'ETL Scope'!I:I,1,0)),"NA","ETL") -> NA | M30: =COUNTIF('Data-WK'!A:A,'V1'!B:B) -> 0 | N30: =VLOOKUP(E30,'IFRS only'!A:A,1,0) -> #N/A
A31: Investment | B31: 1413000120 | C31: 141300 | D31: 可供出售金融资产-基金-公允价值变动 | E31: 120504 | F31: Y | G31: Y | H31: NA | I31: Y | J31: NA | K31: 待Group 决定
A32: Investment | B32: 1413000121 | C32: 141300 | D32: 可供出售金融资产-基金-公允价值变动(手工) | E32: 120504 | F32: Y | G32: NA | H32: NA | I32: NA | J32: NA | K32: 待Group 决定
A33: Investment | B33: 1413000130 | C33: 141300 | D33: 可供出售金融资产-减值准备-基金 | E33: 120505 | F33: Y | G33: Y | H33: NA | I33: Y | J33: NA | K33: 待Group 决定 | L33: =IF(ISERROR(VLOOKUP(B33,'ETL Scope'!I:I,1,0)),"NA","ETL") -> NA | M33: =COUNTIF('Data-WK'!A:A,'V1'!B:B) -> 0 | N33: =VLOOKUP(E33,'IFRS only'!A:A,1,0) -> #N/A
A34: Investment | B34: 1430000000 | C34: 143000 | D34: 交易性金融资产-公允价值选择权-股票(IFRS)-ILP | E34: 121001 | F34: NA | G34: Y | H34: NA | I34: Y | J34: Y | K34: Stocks, Fair Value Option, FAM excl | L34: =IF(ISERROR(VLOOKUP(B34,'ETL Scope'!I:I,1,0)),"NA","ETL") -> NA | M34: =COUNTIF('Data-WK'!A:A,'V1'!B:B) -> 4 | N34: =VLOOKUP(E34,'IFRS only'!A:A,1,0) -> 121001
A35: Investment | B35: 1430002010 | C35: 143000 | D35: 交易性金融资产-股票-成本-ILP | E35: 12010101 | F35: Y | G35: Y | H35: NA | I35: NA | J35: Y-D | K35: 待Group 决定 | L35: =IF(ISERROR(VLOOKUP(B35,'ETL Scope'!I:I,1,0)),"NA","ETL") -> NA | M35: =COUNTIF('Data-WK'!A:A,'V1'!B:B) -> 0 | N35: =VLOOKUP(E35,'IFRS only'!A:A,1,0) -> #N/A
A36: Investment | B36: 1430002020 | C36: 143000 | D36: 交易性金融资产-股票-公允价值变动-ILP | E36: 12010102 | F36: Y | G36: Y | H36: NA | I36: NA | J36: Y-D | K36: 待Group 决定 | L36: =IF(ISERROR(VLOOKUP(B36,'ETL Scope'!I:I,1,0)),"NA","ETL") -> NA | M36: =COUNTIF('Data-WK'!A:A,'V1'!B:B) -> 0 | N36: =VLOOKUP(E36,'IFRS only'!A:A,1,0) -> #N/A
A37: Investment | B37: 1433000000 | C37: 143300 | D37: 交易性金融资产-公允价值选择权-基金(IFRS)-ILP | E37: 121001 | F37: NA | G37: Y | H37: NA | I37: Y | J37: Y | K37: Mutual Funds, Fair Value Option, FAM excl | L37: =IF(ISERROR(VLOOKUP(B37,'ETL Scope'!I:I,1,0)),"NA","ETL") -> NA | M37: =COUNTIF('Data-WK'!A:A,'V1'!B:B) -> 3 | N37: =VLOOKUP(E37,'IFRS only'!A:A,1,0) -> 121001
A38: Investment | B38: 1433000010 | C38: 143300 | D38: 交易性金融资产-基金-成本-ILP | E38: 新增 | F38: Y | G38: Y | H38: NA | I38: NA | J38: Y | K38: 待Group 决定 | L38: =IF(ISERROR(VLOOKUP(B38,'ETL Scope'!I:I,1,0)),"NA","ETL") -> NA | M38: =COUNTIF('Data-WK'!A:A,'V1'!B:B) -> 0 | N38: =VLOOKUP(E38,'IFRS only'!A:A,1,0) -> #N/A
A39: Investment | B39: 1433000020 | C39: 143300 | D39: 交易性金融资产-基金-公允价值变动-ILP | E39: 12010102 | F39: Y | G39: Y | H39: NA | I39: NA | J39: Y-D | K39: 待Group 决定 | L39: =IF(ISERROR(VLOOKUP(B39,'ETL Scope'!I:I,1,0)),"NA","ETL") -> NA | M39: =COUNTIF('Data-WK'!A:A,'V1'!B:B) -> 0 | N39: =VLOOKUP(E39,'IFRS only'!A:A,1,0) -> #N/A
A40: Investment | B40: 1444000000 | C40: 144400 | D40: 可供出售金融资产-货币基金(存款)-成本 | E40: 120501 | F40: Y | G40: Y | H40: NA | I40: Y | J40: NA | K40: Money Market Funds (Deposits), FAM excl | L40: =IF(ISERROR(VLOOKUP(B40,'ETL Scope'!I:I,1,0)),"NA","ETL") -> NA | M40: =COUNTIF('Data-WK'!A:A,'V1'!B:B) -> 1 | N40: =VLOOKUP(E40,'IFRS only'!A:A,1,0) -> #N/A
...

Sheet Sheet1
A1: 整理 分类 | B1: S4 OCOA | C1: OCOA name (CN) | D1: OCOA name (EN)
A2: Term Deposit | B2: 2850010000 | C2: 三个月以内定期存款-RMB-工行 | D2: Non Negotiable TDs =< 90 days, FAM excl
A3: Investment | B3: 1430001010 | C3: 一般交易金融资产-成本-股票 | D3: #N/A
A4: Investment | B4: 1030001010 | C4: 一般交易金融资产-成本-债券 | D4: #N/A
A5: Investment | B5: 1433001010 | C5: 一般交易金融资产-成本-基金 | D5: #N/A
A6: Investment | B6: 1444101500 | C6: 一般交易金融资产-成本-货币式基金 | D6: Money Market Funds (Cash & Cash Equi.)
A7: Investment | B7: 1430001020 | C7: 一般交易金融资产-公允价值变动-股票 | D7: #N/A
A8: Investment | B8: 1030001020 | C8: 一般交易金融资产-公允价值变动-债券 | D8: #N/A
A9: Investment | B9: 1433001020 | C9: 一般交易金融资产-公允价值变动-基金 | D9: #N/A
A10: Investment | B10: 1300000000 | C10: 股票供股权-成本 | D10: Derivatives Assets,Fair Value Option,FAM excl
A11: Investment | B11: 2860011000 | C11: 债券逆回购-面值 | D11: Reverse Repo =< 90 days
A12: Investment | B12: 1143111000 | C12: 债券逆回购-面值 | D12: Reverse Repo >90 days <1 year
A13: Investment | B13: 1143011000 | C13: 债券逆回购-面值 | D13: Reverse Repo >=1 year
A14: Investment | B14: 2860010000 | C14: 债券逆回购-面值 | D14: Reverse Repo =< 90 days, FAM excl
A15: Investment | B15: 1143110000 | C15: 债券逆回购-面值 | D15: Reverse Repo >90 days <1 year, FAM excl
A16: Investment | B16: 1143010000 | C16: 债券逆回购-面值 | D16: Reverse Repo >=1 year, FAM excl
A17: Term Deposit | B17: 1140110000 | C17: 普通定存-一年以下-RMB-工行 | D17: Non Neg TDs > 90 days <1 year, FAM excl
A18: Term Deposit | B18: 1140000000 | C18: 普通定存-一年及以上-RMB-工行 | D18: Long Term Deposits>=1 year, FAM excl
A19: Term Deposit | B19: 114000 待group开code,FAM | C19: 协议定期存款-RMB-工行 | D19: #N/A
A20: Investment | B20: 141000 待Gorup开code,FAM | C20: 可供出售金融资产-成本-股票 | D20: #N/A
A21: Investment | B21: 141000待Gorup开code, FAM | C21: 可供出售金融资产-成本-股票 | D21: #N/A
A22: Investment | B22: 141300 待Gorup开code, FAM | C22: 可供出售金融资产-成本-基金 | D22: #N/A
A23: Investment | B23: 141300待Gorup开code, FAM | C23: 可供出售金融资产-成本-基金 | D23: #N/A
A24: Investment | B24: 1010002000 | C24: 可供出售金融资产-成本-债券 | D24: Available for Sales Securities-NominalVal,FAM excl
A25: Investment | B25: 1444100000 | C25: 可供出售金融资产-成本-货币式基金 | D25: Money Market Funds (Cash & Cash Equiv), FAM excl
A26: Investment | B26: 1444000000 | C26: 可供出售金融资产-成本-货币式基金 | D26: Money Market Funds (Deposits), FAM excl
A27: Investment | B27: 1010002010 | C27: 可供出售金融资产-溢折价摊销-债券 | D27: AFS Securities-Unamort Prem/Disc, FAM excl
A28: Investment | B28: 1010002020 | C28: 可供出售金融资产-公允价值变动-债券 | D28: AFS Securities-Mark to Market change,FAM excl
A29: Investment | B29: 1010002030 | C29: 可供出售金融资产减值准备-债券 | D29: AFS Securities-Prov for Impairment,FAM excl
A30: Investment | B30: 1010000000 | C30: 可供出售金融资产-BOND (IFRS) | D30: Bonds, Available for Sale, FAM excl
A31: Investment | B31: 1000002000 | C31: 持有至到期投资-成本 | D31: Held to Maturity Securities-Nominal Value,FAM excl
A32: Investment | B32: 1000002010 | C32: 持有至到期投资-溢折价摊销 | D32: Held to Maturity Secur-Unamort Prem/Disc,FAM excl
A33: Investment | B33: 1000002020 | C33: 持有至到期投资减值准备 | D33: # 49 OCOA to create in S4 - 11 个保费相关科目，应收保费按按账龄拆分（监管报告），保费收入、预收保费按系统分 （ 对账需求）。 - 17 个投连险账户价值，保户储金及投资款科目：ILP AV roll-forward , 保户储金及投资款-ASO递延收益/万能险账户价值/GUL万能险账户价值… R3 OCOA PH's contract deposits for UL products,Acc.Int.
A34: Insurance cash items | B34: 1243000000 | C34: 保户质押贷款-本金 | D34: Policy Loans
A35: Investment | B35: 1240000000 | C35: 非标投资-本金 | D35: Collateral & Guaranteed Loans, FAM excl
... A41: Investment | B41: 2610000010 | C41: 应收股利-股票股利 | D41: Accrued Investment Income - Dividend
A42: Investment | B42: 260000 待Group开code,FAM | C42: 应收利息-三个月以内定期存款 | D42: #N/A
A43: Investment | B43: 2600000020 | C43: 应收利息-三个月以内定期存款 | D43: Accrued Investments Income, Interest,Bank Interest
A44: Investment | B44: 2600001500 | C44: 应收利息-一般交易性金融资产 | D44: Accrued Investments Income, Interest
A45: Investment | B45: 2600002040 | C45: 应收利息-买入返售金融资产 | D45: Interest Receivable - Reverse Repos, FAM excl
...

Sheet Table
A1: Account Category | B1: Value Range | D1: Chart of Accounts | E1: Account Group | F1: From G/L account | G1: To G/L account | H1: Meaning | J1: BPC ByLine (IFRS) | K1: Segment | L1: BPC ByLine (IFRS) Description | M1: IRBY | N1: IRBY name | P1: T1X2 | Q1: T1X2 des | R1: INS/INV
A2: 1. Assets | B2: 100000 – 299999 | D2: AIA | E2: 10 | F2: 100000 | G2: 109999 | H2: 10 Debit Securities | J2: IBY1111 | K2: All | L2: Premium - FY | M2: IRBY1110 | N2: Premium - First Year | P2: CL | Q2: Credit Life | R2: INS
A3: 2. Liabilities | B3: 300000 – 449999 | D3: AIA | E3: 11 | F3: 110000 | G3: 119999 | H3: 11 Deposits and Short Term Inv | J3: IBY1211 | K3: All | L3: Premium - Ren | M3: IRBY1210 | N3: Premium - Renewal | P3: DA | Q3: Pension UL | R3: INS
A4: 3. Equities | B4: 450000 – 499999 | D4: AIA | E4: 12 | F4: 120000 | G4: 129999 | H4: 12 Loans and Receivables | J4: IBY1311 | K4: All | L4: Premium - Single | M4: IRBY1300 | N4: Premium - Single | P4: DB | Q4: Pension ILP | R4: INS
A5: 4. Insurance Revenue | B5: 500000 – 599999 | D5: AIA | E5: 13 | F5: 130000 | G5: 139999 | H5: 13 Derivative Assets | J5: IBY2111 | K5: All | L5: Inward Reins - Premium - First Year | M5: IRBY2100 | N5: Inward reins | P5: DF | Q5: Deferrd Fixed Annuity | R5: INS
A6: 5. Insurance Expenses | B6: 600000 – 699999 | D6: AIA | E6: 14 | F6: 140000 | G6: 149999 | H6: 14 Equity securities | J6: IBY2121 | K6: All | L6: Inward Reins - Premium - Renewal | M6: IRBY2100 | N6: Inward reins | P6: DV | Q6: Deferrd Variable Annuity | R6: INS
A7: 6. Investment Revenue | B7: 700000 – 729999 | D7: AIA | E7: 15 | F7: 150000 | G7: 159999 | H7: 15 Separate & Var acct assets | J7: IBY2131 | K7: All | L7: Inward Reins - Premium - Single | M7: IRBY2100 | N7: Inward reins | P7: FA | Q7: IRS-OL | R7: INS
A8: 7. Gains and Losses | B8: 730000 – 789999 | D8: AIA | E8: 20 | F8: 200000 | G8: 209999 | H8: 20 Property, Plant & Equipment | J8: IBY2211 | K8: All | L8: Outward Reins - First Year | M8: IRBY2200 | N8: Outward reins | P8: GA | Q8: Group Accident | R8: INS
A9: 8. Investment Expenses | B9: 790000 – 791999 | D9: AIA | E9: 21 | F9: 210000 | G9: 219999 | H9: 21 Investment Real Estate | J9: IBY2221 | K9: All | L9: Outward Reins - Renewal | M9: IRBY2200 | N9: Outward reins | P9: GL | Q9: Group Life | R9: INS
A10: 9. Foreign Currency Translation | B10: 798000 – 799999 | D10: AIA | E10: 22 | F10: 220000 | G10: 229999 | H10: 22 Intangible assets | J10: IBY2231 | K10: All | L10: Outward Reins - Single | M10: IRBY2200 | N10: Outward reins | P10: GM | Q10: Group Medical | R10: INS
A11: 10. General and Operating Expenses (GOE) | B11: 800000 – 879999 | D11: AIA | E11: 23 | F11: 230000 | G11: 239999 | H11: 23 Investment in Associates | J11: IBY1121 | K11: All | L11: Premium - FY Due | M11: IRBY1120 | N11: Premium - First Year - Due | P11: GP | Q11: Group Permanent UL | R11: INS
A12: 11. Taxes | B12: 880000 – 889999 | D12: AIA | E12: 24 | F12: 240000 | G12: 249999 | H12: 24 Investment in Subsidiaries | J12: IBY1221 | K12: All | L12: Premium - Ren Due | M12: IRBY1220 | N12: Premium - Renewal - Due | P12: GQ | Q12: Group Permanent ILP | R12: INS
A13: 12. Other Expenses | B13: 890000 – 899999 (Except for 899000) | D13: AIA | E13: 25 | F13: 250000 | G13: 259999 | H13: 25 Trade Receivables | J13: IBY2112 | K13: All | L13: Inward Reins - Profit com - First Year | M13: IRBY2100 | N13: Inward reins | P13: MG | Q13: Mortgage | R13: INS
A14: 13. Dividend to Shareholders | B14: 899000 | D14: AIA | E14: 26 | F14: 260000 | G14: 269999 | H14: 26 Accrued Investment Income | J14: IBY2122 | K14: All | L14: Inward Reins - Profit Commission - Renewal | M14: IRBY2100 | N14: Inward reins | P14: OL | Q14: Ordinary Life | R14: INS
A15: 14. Control and Suspense | B15: 900000 – 999999 | D15: AIA | E15: 27 | F15: 270000 | G15: 279999 | H15: 27 Other Assets | J15: IBY2132 | K15: All | L15: Inward Reins - Profit Commission - Single | M15: IRBY2100 | N15: Inward reins | P15: HN | Q15: HNW-Npar | R15: INS
D16: AIA | E16: 28 | F16: 280000 | G16: 289999 | H16: 28 Cash & cash equivalents | J16: IBY2212 | K16: All | L16: Outward Reins - Profit com - First Year | M16: IRBY2200 | N16: Outward reins | P16: HP | Q16: HNW-par | R16: INS
D17: AIA | E17: 29 | F17: 290000 | G17: 299999 | H17: 29 Assets Held For Sales | J17: IBY2222 | K17: All | L17: Outward Reins - Profit com - Renewal | M17: IRBY2200 | N17: Outward reins | P17: HO | Q17: HNW-par(PH 90%) | R17: INS
D18: AIA | E18: 30 | F18: 300000 | G18: 309999 | H18: 30 Insurance Contracts Liab | J18: IBY2232 | K18: All | L18: Outward Reins - Profit com - Single | M18: IRBY2200 | N18: Outward reins | P18: PA | Q18: Personal Accident | R18: INS
D19: AIA | E19: 31 | F19: 310000 | G19: 319999 | H19: 31 Future Policy Benefit Liab | J19: IBY4111 | K19: All | L19: Change in Insurance Contract Liabilities - Direct | M19: IRBY4110 | N19: Change in insurance contract liabilities | P19: UL | Q19: Universal Life | R19: INS
D20: AIA | E20: 35 | F20: 350000 | G20: 359999 | H20: 35 Policyholders' Contract Dep | J20: IBY2311 | K20: All | L20: Fee Income | M20: IRBY2300 | N20: Expected fee income | P20: UA | Q20: UL-UCX1501 | R20: INS
D21: AIA | E21: 37 | F21: 370000 | G21: 379999 | H21: 37 Other Policyholders' Funds | J21: IBY3411 | K21: All | L21: Surrenders - Direct | M21: IRBY3400 | N21: Surrenders | P21: IL | Q21: Investment Linked | R21: INS
D22: AIA | E22: 38 | F22: 380000 | G22: 399999 | H22: 38 Unearned revenues; reserves | J22: IBY2411 | K22: All | L22: Premium (Reserves) | M22: IRBY2400 | N22: Premium (reserves) | P22: VA | Q22: IRS-UL | R22: INS
D23: AIA | E23: 40 | F23: 400000 | G23: 409999 | H23: 40 Financial Liabilities | J23: IBY2511 | K23: All | L23: Other Revenue | M23: IRBY2500 | N23: Other revenue | P23: OX | Q23: OL PAR | R23: INS
D24: AIA | E24: 41 | F24: 410000 | G24: 419999 | H24: 41 Tax Liabilities | J24: IBY3111 | K24: All | L24: Claims - Direct | M24: IRBY3110 | N24: Claims | P24: OS | Q24: OL PAR(SPE) | R24: INS
D25: AIA | E25: 42 | F25: 420000 | G25: 429999 | H25: 42 Trade & Other Payables | J25: IBY3131 | K25: All | L25: Inward Reins Claims | M25: IRBY3130 | N25: Inward reins. claims | P25: HA | Q25: HNW/HEM-PA | R25: INS
D26: AIA | E26: 43 | F26: 430000 | G26: 439999 | H26: 43 Provisions | J26: IBY4311 | K26: All | L26: Outward Reins. Claims | M26: IRBY4311 | N26: Outward Reins. claims | P26: CK | Q26: Common Stock - offshore (non H share) | R26: INV
D27: AIA | E27: 44 | F27: 440000 | G27: 449999 | H27: 44 Liabilities held for sale | J27: IBY3121 | K27: All | L27: Claims (Reserves) - Direct | M27: IRBY3120 | N27: Claims (reserves) | P27: CA | Q27: Common Stock-A-Share | R27: INV
... D58: AIA | E58: 99 | F58: 990000 | G58: 999999 | H58: 99 Interface Control Accounts | J58: IBY5313 | K58: All | L58: Acq. Exp. Inward - Single | M58: IRBY5310 | N58: Acquisition Exp. - Rein comm | P58: CZ | Q58: Corp/Fixed offshore | R58: INV
J59: IBY5321 | K59: All | L59: Acq. Exp. Outward - First Year | M59: IRBY5310 | N59: Acquisition Exp. - Rein comm | P59: CJ | Q59: Corp/Floating offshore | R59: INV
J60: IBY5322 | K60: All | L60: Acq. Exp. Outward - Renewal | M60: IRBY5310 | N60: Acquisition Exp. - Rein comm | P60: GH | Q60: Government offshore | R60: INV
J61: IBY5323 | K61: All | L61: Acq. Exp. Outward - Single | M61: IRBY5310 | N61: Acquisition Exp. - Rein comm | P61: MI | Q61: Mutual Fund offshore | R61: INV
J62: IBY5211 | K62: All | L62: Acq. Exp. Due/Unearned - First Year | M62: IRBY5210 | N62: Acquisition Exp. - Due | P62: FH | Q62: Financial bond offshore | R62: INV
J63: IBY5212 | K63: All | L63: Acq. Exp. Due/Unearned - Renewal | M63: IRBY5210 | N63: Acquisition Exp. - Due | P63: MO | Q63: Money market fund offshore | R63: INV
J64: IBY5213 | K64: All | L64: Acq. Exp. Due/Unearned - Single | M64: IRBY5210 | N64: Acquisition Exp. - Due | P64: MB | Q64: Mortgage backed security | R64: INV
J65: IBY5411 | K65: All | L65: Change In DAC - Commission - Deferral | M65: IRBY5410 | N65: Change In DAC - commission - deferral | P65: CD | Q65: Negotiable certificates of deposit (同业存单） | R65: INV
J66: IBY5421 | K66: All | L66: Change In DAC - Operating Exps - Deferral | M66: IRBY5420 | N66: Change In DAC - operating exps - deferral | P66: RE | Q66: Real estate debt plan(不动产债权投资计划) | R66: INV
J67: IBY5431 | K67: All | L67: Change In DAC - Comm & Oper Exps - Amort Normal | M67: IRBY5430 | N67: Change In DAC - comm & oper exps - amort. Normal
J68: IBY5441 | K68: All | L68: Change In DAC - Comm & Oper Exps - Amort Others | M68: IRBY5440 | N68: Change In DAC - comm & oper exps - amort. Others
J69: IBY7111 | K69: All | L69: Interest Income | M69: IRBY7110 | N69: Interest Income
J70: IBY0211 | K70: All | L70: Inv Income related to Unit-Linked Contracts | M70: IRBY0210 | N70: Investment income related to Inv-Linked contracts
...

Sheet Data-WK
F1: SUN Code | G1: S4 OCOA | H1: A | I1: I
F2: 11030101 | G2: 2850010000 | H2: =[2]!a_eb("CDT,{P1},,2017013,,YA,,,","K=Acc_Code,F={P2},O=B",H$1,$F2) -> #NAME? | I2: =[2]!a_eb("CDT,{P1},,2017013,,YA,,,","K=Acc_Code,F={P2},O=B",I$1,$F2) -> #NAME?
F3: 12010101 | G3: 1430001010 | H3: =[2]!a_eb("CDT,{P1},,2017013,,YA,,,","K=Acc_Code,F={P2},O=B",H$1,$F3) -> #NAME? | I3: =[2]!a_eb("CDT,{P1},,2017013,,YA,,,","K=Acc_Code,F={P2},O=B",I$1,$F3) -> #NAME?
F4: 12010101 | G4: 1030001010 | H4: =[2]!a_eb("CDT,{P1},,2017013,,YA,,,","K=Acc_Code,F={P2},O=B",H$1,$F4) -> #NAME? | I4: =[2]!a_eb("CDT,{P1},,2017013,,YA,,,","K=Acc_Code,F={P2},O=B",I$1,$F4) -> #NAME?
F5: 12010101 | G5: 1433001010 | H5: =[2]!a_eb("CDT,{P1},,2017013,,YA,,,","K=Acc_Code,F={P2},O=B",H$1,$F5) -> #NAME? | I5: =[2]!a_eb("CDT,{P1},,2017013,,YA,,,","K=Acc_Code,F={P2},O=B",I$1,$F5) -> #NAME?
A6: S4 OCOA | B6: 科目代码 | F6: 12010101 | G6: 1444101500 | H6: =[2]!a_eb("CDT,{P1},,2017013,,YA,,,","K=Acc_Code,F={P2},O=B",H$1,$F6) -> #NAME? | I6: =[2]!a_eb("CDT,{P1},,2017013,,YA,,,","K=Acc_Code,F={P2},O=B",I$1,$F6) -> #NAME?
A7: 2800020000 | B7: 110101 | C7: =VLOOKUP(B7,F:G,2,0) -> #N/A | F7: 12010102 | G7: 1430001020 | H7: =[2]!a_eb("CDT,{P1},,2017013,,YA,,,","K=Acc_Code,F={P2},O=B",H$1,$F7) -> #NAME? | I7: =[2]!a_eb("CDT,{P1},,2017013,,YA,,,","K=Acc_Code,F={P2},O=B",I$1,$F7) -> #NAME?
A8: 2800000000 | B8: 110102 | C8: =VLOOKUP(B8,F:G,2,0) -> #N/A | F8: 12010102 | G8: 1030001020 | H8: =[2]!a_eb("CDT,{P1},,2017013,,YA,,,","K=Acc_Code,F={P2},O=B",H$1,$F8) -> #NAME? | I8: =[2]!a_eb("CDT,{P1},,2017013,,YA,,,","K=Acc_Code,F={P2},O=B",I$1,$F8) -> #NAME?
A9: 2800011500 | B9: 110103 | C9: =VLOOKUP(B9,F:G,2,0) -> #N/A | F9: 12010102 | G9: 1433001020 | H9: =[2]!a_eb("CDT,{P1},,2017013,,YA,,,","K=Acc_Code,F={P2},O=B",H$1,$F9) -> #NAME? | I9: =[2]!a_eb("CDT,{P1},,2017013,,YA,,,","K=Acc_Code,F={P2},O=B",I$1,$F9) -> #NAME?
A10: New ICBC CNY 4 | B10: 1102010101 | C10: =VLOOKUP(B10,F:G,2,0) -> #N/A | F10: 12010301 | G10: 1300000000 | H10: =[2]!a_eb("CDT,{P1},,2017013,,YA,,,","K=Acc_Code,F={P2},O=B",H$1,$F10) -> #NAME? | I10: =[2]!a_eb("CDT,{P1},,2017013,,YA,,,","K=Acc_Code,F={P2},O=B",I$1,$F10) -> #NAME?
A11: 2820050200 | B11: 1102010103 | C11: =VLOOKUP(B11,F:G,2,0) -> #N/A | F11: 12030101 | G11: 2860011000 | H11: =[2]!a_eb("CDT,{P1},,2017013,,YA,,,","K=Acc_Code,F={P2},O=B",H$1,$F11) -> #NAME? | I11: =[2]!a_eb("CDT,{P1},,2017013,,YA,,,","K=Acc_Code,F={P2},O=B",I$1,$F11) -> #NAME?
A12: New ICBC CNY 8 | B12: 1102010104 | C12: =VLOOKUP(B12,F:G,2,0) -> #N/A | F12: 12030101 | G12: 1143111000 | H12: =[2]!a_eb("CDT,{P1},,2017013,,YA,,,","K=Acc_Code,F={P2},O=B",H$1,$F12) -> #NAME? | I12: =[2]!a_eb("CDT,{P1},,2017013,,YA,,,","K=Acc_Code,F={P2},O=B",I$1,$F12) -> #NAME?
A13: New ICBC CNY 6 | B13: 1102010106 | C13: =VLOOKUP(B13,F:G,2,0) -> #N/A | F13: 12030101 | G13: 1143011000 | H13: =[2]!a_eb("CDT,{P1},,2017013,,YA,,,","K=Acc_Code,F={P2},O=B",H$1,$F13) -> #NAME? | I13: =[2]!a_eb("CDT,{P1},,2017013,,YA,,,","K=Acc_Code,F={P2},O=B",I$1,$F13) -> #NAME?
A14: New ICBC CNY 13 | B14: 1102010107 | C14: =VLOOKUP(B14,F:G,2,0) -> #N/A | F14: 12030101 | G14: 2860010000 | H14: =[2]!a_eb("CDT,{P1},,2017013,,YA,,,","K=Acc_Code,F={P2},O=B",H$1,$F14) -> #NAME? | I14: =[2]!a_eb("CDT,{P1},,2017013,,YA,,,","K=Acc_Code,F={P2},O=B",I$1,$F14) -> #NAME?
A15: New ICBC CNY 9 | B15: 1102010108 | C15: =VLOOKUP(B15,F:G,2,0) -> #N/A | F15: 12030101 | G15: 1143110000 | H15: =[2]!a_eb("CDT,{P1},,2017013,,YA,,,","K=Acc_Code,F={P2},O=B",H$1,$F15) -> #NAME? | I15: =[2]!a_eb("CDT,{P1},,2017013,,YA,,,","K=Acc_Code,F={P2},O=B",I$1,$F15) -> #NAME?
A16: 2820050000 | B16: 1102010110 | C16: =VLOOKUP(B16,F:G,2,0) -> #N/A | F16: 12030101 | G16: 1143010000 | H16: =[2]!a_eb("CDT,{P1},,2017013,,YA,,,","K=Acc_Code,F={P2},O=B",H$1,$F16) -> #NAME? | I16: =[2]!a_eb("CDT,{P1},,2017013,,YA,,,","K=Acc_Code,F={P2},O=B",I$1,$F16) -> #NAME?
A17: 2820050000 | B17: 1102010111 | C17: =VLOOKUP(B17,F:G,2,0) -> #N/A | F17: 1204010101 | G17: 1140110000 | H17: =[2]!a_eb("CDT,{P1},,2017013,,YA,,,","K=Acc_Code,F={P2},O=B",H$1,$F17) -> #NAME? | I17: =[2]!a_eb("CDT,{P1},,2017013,,YA,,,","K=Acc_Code,F={P2},O=B",I$1,$F17) -> #NAME?
A18: 2820050000 | B18: 1102010112 | C18: =VLOOKUP(B18,F:G,2,0) -> #N/A | F18: 1204020101 | G18: 1140000000 | H18: =[2]!a_eb("CDT,{P1},,2017013,,YA,,,","K=Acc_Code,F={P2},O=B",H$1,$F18) -> #NAME? | I18: =[2]!a_eb("CDT,{P1},,2017013,,YA,,,","K=Acc_Code,F={P2},O=B",I$1,$F18) -> #NAME?
A19: 2820050000 | B19: 1102010113 | C19: =VLOOKUP(B19,F:G,2,0) -> #N/A | F19: 1204030101 | G19: 114000 待group开code,FAM | H19: =[2]!a_eb("CDT,{P1},,2017013,,YA,,,","K=Acc_Code,F={P2},O=B",H$1,$F19) -> #NAME? | I19: =[2]!a_eb("CDT,{P1},,2017013,,YA,,,","K=Acc_Code,F={P2},O=B",I$1,$F19) -> #NAME?
A20: 2820050000 | B20: 1102010114 | C20: =VLOOKUP(B20,F:G,2,0) -> #N/A | F20: 120501 | G20: 141000 待Gorup开code,FAM | H20: =[2]!a_eb("CDT,{P1},,2017013,,YA,,,","K=Acc_Code,F={P2},O=B",H$1,$F20) -> #NAME? | I20: =[2]!a_eb("CDT,{P1},,2017013,,YA,,,","K=Acc_Code,F={P2},O=B",I$1,$F20) -> #NAME?
A21: 2820050000 | B21: 1102010115 | C21: =VLOOKUP(B21,F:G,2,0) -> #N/A | F21: 120501 | G21: 141000待Gorup开code, FAM | H21: =[2]!a_eb("CDT,{P1},,2017013,,YA,,,","K=Acc_Code,F={P2},O=B",H$1,$F21) -> #NAME? | I21: =[2]!a_eb("CDT,{P1},,2017013,,YA,,,","K=Acc_Code,F={P2},O=B",I$1,$F21) -> #NAME?
A22: 2820050000 | B22: 1102010116 | C22: =VLOOKUP(B22,F:G,2,0) -> #N/A | F22: 120501 | G22: 141300 待Gorup开code, FAM | H22: =[2]!a_eb("CDT,{P1},,2017013,,YA,,,","K=Acc_Code,F={P2},O=B",H$1,$F22) -> #NAME? | I22: =[2]!a_eb("CDT,{P1},,2017013,,YA,,,","K=Acc_Code,F={P2},O=B",I$1,$F22) -> #NAME?
A23: New ICBC CNY 3 | B23: 1102010117 | C23: =VLOOKUP(B23,F:G,2,0) -> #N/A | F23: 120501 | G23: 141300待Gorup开code, FAM | H23: =[2]!a_eb("CDT,{P1},,2017013,,YA,,,","K=Acc_Code,F={P2},O=B",H$1,$F23) -> #NAME? | I23: =[2]!a_eb("CDT,{P1},,2017013,,YA,,,","K=Acc_Code,F={P2},O=B",I$1,$F23) -> #NAME?
A24: New ICBC CNY 3 | B24: 1102010122 | C24: =VLOOKUP(B24,F:G,2,0) -> #N/A | F24: 120501 | G24: 1010002000 | H24: =[2]!a_eb("CDT,{P1},,2017013,,YA,,,","K=Acc_Code,F={P2},O=B",H$1,$F24) -> #NAME? | I24: =[2]!a_eb("CDT,{P1},,2017013,,YA,,,","K=Acc_Code,F={P2},O=B",I$1,$F24) -> #NAME?
A25: New ICBC CNY 3 | B25: 1102010124 | C25: =VLOOKUP(B25,F:G,2,0) -> #N/A | F25: 120501 | G25: 1444100000 | H25: =[2]!a_eb("CDT,{P1},,2017013,,YA,,,","K=Acc_Code,F={P2},O=B",H$1,$F25) -> #NAME? | I25: =[2]!a_eb("CDT,{P1},,2017013,,YA,,,","K=Acc_Code,F={P2},O=B",I$1,$F25) -> #NAME?
A26: 2820050000 | B26: 1102010127 | C26: =VLOOKUP(B26,F:G,2,0) -> #N/A | F26: 120501 | G26: 1444000000 | H26: =[2]!a_eb("CDT,{P1},,2017013,,YA,,,","K=Acc_Code,F={P2},O=B",H$1,$F26) -> #NAME? | I26: =[2]!a_eb("CDT,{P1},,2017013,,YA,,,","K=Acc_Code,F={P2},O=B",I$1,$F26) -> #NAME?
A27: New ICBC CNY 5 | B27: 1102010128 | C27: =VLOOKUP(B27,F:G,2,0) -> #N/A | F27: 120502 | G27: 1010002010 | H27: =[2]!a_eb("CDT,{P1},,2017013,,YA,,,","K=Acc_Code,F={P2},O=B",H$1,$F27) -> #NAME? | I27: =[2]!a_eb("CDT,{P1},,2017013,,YA,,,","K=Acc_Code,F={P2},O=B",I$1,$F27) -> #NAME?
A28: 2820050000 | B28: 1102010130 | C28: =VLOOKUP(B28,F:G,2,0) -> #N/A | F28: 120504 | G28: 1010002020 | H28: =[2]!a_eb("CDT,{P1},,2017013,,YA,,,","K=Acc_Code,F={P2},O=B",H$1,$F28) -> #NAME? | I28: =[2]!a_eb("CDT,{P1},,2017013,,YA,,,","K=Acc_Code,F={P2},O=B",I$1,$F28) -> #NAME?
A29: 2820050000 | B29: 1102010131 | C29: =VLOOKUP(B29,F:G,2,0) -> #N/A | F29: 120505 | G29: 1010002030 | H29: =[2]!a_eb("CDT,{P1},,2017013,,YA,,,","K=Acc_Code,F={P2},O=B",H$1,$F29) -> #NAME? | I29: =[2]!a_eb("CDT,{P1},,2017013,,YA,,,","K=Acc_Code,F={P2},O=B",I$1,$F29) -> #NAME?
A30: 2820050000 | B30: 1102010132 | C30: =VLOOKUP(B30,F:G,2,0) -> #N/A | F30: 120506 | G30: 1010000000 | H30: =[2]!a_eb("CDT,{P1},,2017013,,YA,,,","K=Acc_Code,F={P2},O=B",H$1,$F30) -> #NAME? | I30: =[2]!a_eb("CDT,{P1},,2017013,,YA,,,","K=Acc_Code,F={P2},O=B",I$1,$F30) -> #NAME?
A31: 2820050000 | B31: 1102010133 | C31: =VLOOKUP(B31,F:G,2,0) -> #N/A | F31: 120601 | G31: 1000002000 | H31: =[2]!a_eb("CDT,{P1},,2017013,,YA,,,","K=Acc_Code,F={P2},O=B",H$1,$F31) -> #NAME? | I31: =[2]!a_eb("CDT,{P1},,2017013,,YA,,,","K=Acc_Code,F={P2},O=B",I$1,$F31) -> #NAME?
A32: 2820050000 | B32: 1102010135 | C32: =VLOOKUP(B32,F:G,2,0) -> #N/A | F32: 120602 | G32: 1000002010 | H32: =[2]!a_eb("CDT,{P1},,2017013,,YA,,,","K=Acc_Code,F={P2},O=B",H$1,$F32) -> #NAME? | I32: =[2]!a_eb("CDT,{P1},,2017013,,YA,,,","K=Acc_Code,F={P2},O=B",I$1,$F32) -> #NAME?
A33: 2820050000 | B33: 1102010136 | C33: =VLOOKUP(B33,F:G,2,0) -> #N/A | F33: 120604 | G33: 1000002020 | H33: =[2]!a_eb("CDT,{P1},,2017013,,YA,,,","K=Acc_Code,F={P2},O=B",H$1,$F33) -> #NAME? | I33: =[2]!a_eb("CDT,{P1},,2017013,,YA,,,","K=Acc_Code,F={P2},O=B",I$1,$F33) -> #NAME?
A34: New ICBC CNY 4 | B34: 1102010137 | C34: =VLOOKUP(B34,F:G,2,0) -> #N/A | F34: 120701 | G34: 1243000000 | H34: =[2]!a_eb("CDT,{P1},,2017013,,YA,,,","K=Acc_Code,F={P2},O=B",H$1,$F34) -> #NAME? | I34: =[2]!a_eb("CDT,{P1},,2017013,,YA,,,","K=Acc_Code,F={P2},O=B",I$1,$F34) -> #NAME?
A35: New ICBC CNY 6 | B35: 1102010139 | C35: =VLOOKUP(B35,F:G,2,0) -> #N/A | F35: 120801 | G35: 1240000000 | H35: =[2]!a_eb("CDT,{P1},,2017013,,YA,,,","K=Acc_Code,F={P2},O=B",H$1,$F35) -> #NAME? | I35: =[2]!a_eb("CDT,{P1},,2017013,,YA,,,","K=Acc_Code,F={P2},O=B",I$1,$F35) -> #NAME?
A36: New ICBC CNY 4 | B36: 1102010142 | C36: =VLOOKUP(B36,F:G,2,0) -> #N/A | F36: 120801 | G36: 1245002000 | H36: =[2]!a_eb("CDT,{P1},,2017013,,YA,,,","K=Acc_Code,F={P2},O=B",H$1,$F36) -> #NAME? | I36: =[2]!a_eb("CDT,{P1},,2017013,,YA,,,","K=Acc_Code,F={P2},O=B",I$1,$F36) -> #NAME?
A37: 2820050000 | B37: 1102010144 | C37: =VLOOKUP(B37,F:G,2,0) -> #N/A | F37: 121001 | G37: 1430000000 | H37: =[2]!a_eb("CDT,{P1},,2017013,,YA,,,","K=Acc_Code,F={P2},O=B",H$1,$F37) -> #NAME? | I37: =[2]!a_eb("CDT,{P1},,2017013,,YA,,,","K=Acc_Code,F={P2},O=B",I$1,$F37) -> #NAME?
A38: 2820050000 | B38: 1102010147 | C38: =VLOOKUP(B38,F:G,2,0) -> #N/A | F38: 121001 | G38: 1433000000 | H38: =[2]!a_eb("CDT,{P1},,2017013,,YA,,,","K=Acc_Code,F={P2},O=B",H$1,$F38) -> #NAME? | I38: =[2]!a_eb("CDT,{P1},,2017013,,YA,,,","K=Acc_Code,F={P2},O=B",I$1,$F38) -> #NAME?
A39: New ICBC CNY 12 | B39: 1102010148 | C39: =VLOOKUP(B39,F:G,2,0) -> #N/A | F39: 121001 | G39: 1030000000 | H39: =[2]!a_eb("CDT,{P1},,2017013,,YA,,,","K=Acc_Code,F={P2},O=B",H$1,$F39) -> #NAME? | I39: =[2]!a_eb("CDT,{P1},,2017013,,YA,,,","K=Acc_Code,F={P2},O=B",I$1,$F39) -> #NAME?
A40: New ICBC CNY 3 | B40: 1102010151 | C40: =VLOOKUP(B40,F:G,2,0) -> #N/A | F40: 130101 | G40: 2610000000 | H40: =[2]!a_eb("CDT,{P1},,2017013,,YA,,,","K=Acc_Code,F={P2},O=B",H$1,$F40) -> #NAME? | I40: =[2]!a_eb("CDT,{P1},,2017013,,YA,,,","K=Acc_Code,F={P2},O=B",I$1,$F40) -> #NAME?
...

Sheet IFRS only
A1: SUN Code
A2: 120506 | B2: =VLOOKUP(A2,'V1'!E:E,1,0) -> 120506
A3: 121001 | B3: =VLOOKUP(A3,'V1'!E:E,1,0) -> 121001
A4: 130315 | B4: =VLOOKUP(A4,'V1'!E:E,1,0) -> 130315
A5: 13070106 | B5: =VLOOKUP(A5,'V1'!E:E,1,0) -> 13070106
A6: 16050501 | B6: =VLOOKUP(A6,'V1'!E:E,1,0) -> 16050501
A7: 16050502 | B7: =VLOOKUP(A7,'V1'!E:E,1,0) -> 16050502
A8: 160001 | B8: =VLOOKUP(A8,'V1'!E:E,1,0) -> 160001
A9: 160002 | B9: =VLOOKUP(A9,'V1'!E:E,1,0) -> 160002
A10: 160003 | B10: =VLOOKUP(A10,'V1'!E:E,1,0) -> 160003
A11: 160004 | B11: =VLOOKUP(A11,'V1'!E:E,1,0) -> 160004
A12: 160005 | B12: =VLOOKUP(A12,'V1'!E:E,1,0) -> 160005
A13: 160006 | B13: =VLOOKUP(A13,'V1'!E:E,1,0) -> 160006
... A73: 550203 | B73: =VLOOKUP(A73,'V1'!E:E,1,0) -> 550203

Sheet ETL Scope
A1: ACCT_CD | B1: AMOUNT | C1: IFRS_CD | D1: BYLINE_CD | F1: Row Labels | G1: Sum of AMOUNT | I1: Row Labels | J1: Sum of AMOUNT
A2: 3710000000 | B2: -185807 | C2: IS02000000 | D2: IBY0000 | F2: 2201000000 | G2: 15661221387 | I2: 2201000000 | J2: 15661221387 | K2: =VLOOKUP(I2,'Data-WK'!A:B,2,0) -> 160001
A3: 6700000000 | B3: 0 | C3: IS05082000 | D3: IBY5411 | F3: 2201000010 | G3: 32296507 | I3: 2201000010 | J3: 32296507 | K3: =VLOOKUP(I3,'Data-WK'!A:B,2,0) -> 160005
A4: 5010100000 | B4: 0 | C4: IS04010000 | D4: IBY1221 | F4: 2201000030 | G4: 49205146 | I4: 2201000030 | J4: 49205146 | K4: =VLOOKUP(I4,'Data-WK'!A:B,2,0) -> 160003
A5: 6700400000 | B5: 0 | C5: IS05082000 | D5: IBY5411 | F5: 2201200030 | G5: -15126751 | I5: 2201200030 | J5: -15126751 | K5: =VLOOKUP(I5,'Data-WK'!A:B,2,0) -> 160004
A6: 4203000000 | B6: 0 | C6: IS02081100 | D6: IBY0000 | F6: 2201300000 | G6: 49088979 | I6: 2201300000 | J6: 49088979 | K6: =VLOOKUP(I6,'Data-WK'!A:B,2,0) -> 160007
A7: 6700200000 | B7: 0 | C7: IS05082000 | D7: IBY5431 | F7: 2201400000 | G7: 134968552 | I7: 2201400000 | J7: 134968552 | K7: =VLOOKUP(I7,'Data-WK'!A:B,2,0) -> 160008
A8: 3103000000 | B8: 0 | C8: IS02000000 | D8: IBY0000 | F8: 2203000000 | G8: 12049381 | I8: 2203000000 | J8: 12049381 | K8: =VLOOKUP(I8,'Data-WK'!A:B,2,0) -> 160002
A9: 6700100000 | B9: 0 | C9: IS05082000 | D9: IBY5421 | F9: 2203000010 | G9: 3244274 | I9: 2203000010 | J9: 3244274 | K9: =VLOOKUP(I9,'Data-WK'!A:B,2,0) -> 160006
A10: 4203000000 | B10: 0 | C10: IS02081100 | D10: IBY0000 | F10: 2500000000 | G10: 1912514542 | I10: 2500000000 | J10: 1912514542 | K10: =VLOOKUP(I10,'Data-WK'!A:B,2,0) -> 13040101
A11: 6700400000 | B11: 0 | C11: IS05082000 | D11: IBY5411 | F11: 2750010000 | G11: 1592476 | I11: 2750010000 | J11: 1592476 | K11: =VLOOKUP(I11,'Data-WK'!A:B,2,0) -> 13070101
A12: 5010000000 | B12: 0 | C12: IS04010000 | D12: IBY1121 | F12: 3030000000 | G12: -489209887 | I12: 3030000000 | J12: -489209887 | K12: =VLOOKUP(I12,'Data-WK'!A:B,2,0) -> 22020201
A13: 4203000000 | B13: 0 | C13: IS02081100 | D13: IBY0000 | F13: 3032000000 | G13: 180946158 | I13: 3032000000 | J13: 180946158 | K13: =VLOOKUP(I13,'Data-WK'!A:B,2,0) -> 14020201
... A61: 3102000000 | B61: 0 | C61: IS01060000 | D61: IBY0000 | F61: 6700700000 | G61: -120980350 | I61: 6700700000 | J61: -120980350 | K61: =VLOOKUP(I61,'Data-WK'!A:B,2,0) -> 5106050510
A62: 6700200000 | B62: 0 | C62: IS05082000 | D62: IBY5431 | F62: (blank) | I62: (blank)
A63: 2500000000 | B63: 0 | C63: IS01220000 | D63: IBY0000 | F63: Grand Total | G63: 0 | I63: Grand Total | J63: 0
A64: 4203000000 | B64: 0 | C64: IS02081100 | D64: IBY0000
A65: 6700700000 | B65: 0 | C65: IS05082000 | D65: IBY5431
A66: 6700500000 | B66: 0 | C66: IS05082000 | D66: IBY5411
A67: 5052010000 | B67: 0 | C67: IS04010000 | D67: IBY2411
A68: 2203000000 | B68: 0 | C68: IS01070000 | D68: IBY0000
A69: 6700000000 | B69: 0 | C69: IS05082000 | D69: IBY5411
A70: 3800000000 | B70: 0 | C70: IS02000000 | D70: IBY0000
A71: 6104001000 | B71: -114928 | C71: IS05031000 | D71: IBY4111
A72: 5010000000 | B72: 0 | C72: IS04010000 | D72: IBY1121
A73: 6102000000 | B73: 0 | C73: IS05040000 | D73: IBY4313
A74: 5010000010 | B74: 0 | C74: IS04010000 | D74: IBY1121
A75: 6700200000 | B75: 0 | C75: IS05082000 | D75: IBY5431
... A7947: 5010100000 | B7947: -614189 | C7947: IS04010000 | D7947: IBY1221
